Workbook
Name boxmaterials: [1]!Table1[Material de construcție]
Name PHPP_Daten_Komponentensortierung: [2]Data!$A$194:$A$195
Name PHPP_Flaechen_Liste_Bauteile: [2]Areas!$AN$40:$AN$139
Name PHPP_Komponenten_Liste_Bauteilaufbauten: [2]Components!$FZ$12:$FZ$412
Name PHPP_Komponenten_Liste_Fensterrahmen: [2]Components!$GH$12:$GH$412
Name PHPP_Komponenten_Liste_Verglasung: [2]Components!$GD$12:$GD$412
Name PHPP_Komponenten_Liste_Waermerueckgewinnungsgeraet: [2]Components!$GL$12:$GL$412

Sheet Intro
B2: Current calculation tool can serve a basis for elaboration of energy audit report in buildings.
B4: Tables with input data and calculations have to be attached as an annex to the energy audit report.
B6: Indications for use:
B8: Tables can be multiplied or modified depending on various situations, rows and columns can be deleted, added or combined.
D11: Cells which require input data or text
D13: Cells with automatic calculations or text
D15: Cells which are advised to remain unchanged, but not mandatory.
B17: The energy auditor is free to add graphs, or improve the tool in any way he considers relevant
B18: Energy consumption can be expressed in various units of measure, further all calculations to be done in kWh.
B20: Calculations related to water savings are not considered by the current tool, it can be developed further by the auditor in case if it will be required.
B23: The values and contents (formulas, links etc.) of the spreadsheet provided as a input data for energy audit report is in full responsability of the energy auditor.

Sheet Sheet1
A1: Республика, вилоят, жой | B1: Ойлик ўртача ҳарорат | N1: Ўртача йиллик ҳарорат | O1: Энг кичик мутлақ ҳарорат | P1: Энг катта мутлақ ҳарорат | Q1: Энг иссиқ ойдаги энг катта ўртача ҳарорат | R1: Энг совуқ ойдаги энг кичик ўртача ҳарорат
B2: I | C2: II | D2: III | E2: IV | F2: V | G2: VI | H2: VII | I2: VIII | J2: IX | K2: X | L2: XI | M2: XII
A3: 1 | B3: 2 | C3: 3 | D3: 4 | E3: 5 | F3: 6 | G3: 7 | H3: 8 | I3: 9 | J3: 10 | K3: 11 | L3: 12 | M3: 13 | N3: 14 | O3: 15 | P3: 16 | Q3: 17 | R3: 18
A4: Тошкент вилояти
A5: Тошкент | B5: 1,9 | C5: 3,9 | D5: 9,4 | E5: 15,5 | F5: 20,5 | G5: 25,8 | H5: 27,8 | I5: 26,2 | J5: 20,6 | K5: 13,8 | L5: 8,5 | M5: 3,5 | N5: 14,8 | O5: =-29.5/1930 -> -0.015284974 | P5: 44.6/1997 | Q5: 35,6 | R5: -1,5
A6: Янгийўл | B6: 0,4 | C6: 2,9 | D6: 9,0 | E6: 15,6 | F6: 21,1 | G6: 26,3 | H6: 27,8 | I6: 25,7 | J6: 20,2 | K6: 13,5 | L6: 7,3 | M6: 1,7 | N6: 14,3 | O6: =-32/1930 -> -0.016580311 | P6: 45.5/1998 | Q6: 36,2 | R6: -3,1
A7: Туябўғуз | B7: 1,1 | C7: 3,5 | D7: 9,3 | E7: 16,0 | F7: 21,2 | G7: 26,3 | H7: 27,8 | I7: 26,1 | J7: 21,1 | K7: 14,5 | L7: 8,3 | M7: 2,6 | N7: 14,8 | O7: =-27.1/1969 -> -0.013763332 | P7: 42.7/1983 | Q7: 35,2 | R7: -2,1
A8: Кўкорол | B8: -0,1 | C8: 2,5 | D8: 8,6 | E8: 15,3 | F8: 20,3 | G8: 24,7 | H8: 25,7 | I8: 23,6 | J8: 18,4 | K8: 12,4 | L8: 6,6 | M8: 1,2 | N8: 13,3 | O8: =-32.2/1969 -> -0.016353479 | P8: 46.1/1944 | Q8: 34,3 | R8: -3,8
A9: Далварзин | B9: 1,5 | C9: 4,1 | D9: 9,9 | E9: 16,5 | F9: 21,8 | G9: 26,7 | H9: 27,7 | I9: 25,4 | J9: 20,2 | K9: 14,1 | L9: 8,3 | M9: 2,9 | N9: 14,9 | O9: =-35/1930 -> -0.018134715 | P9: 43.5/2005 | Q9: 35,2 | R9: -2,2
A10: Бекобод | B10: 1,6 | C10: 3,8 | D10: 9,8 | E10: 16,4 | F10: 21,6 | G10: 26,4 | H10: 27,6 | I10: 25,5 | J10: 20,4 | K10: 14,2 | L10: 8,6 | M10: 3,0 | N10: 14,9 | O10: =-30.2/1930 -> -0.015647668 | P10: 43.8/1944 | Q10: 34,8 | R10: -0,9
A11: Олмалиқ | B11: 1,5 | C11: 3,7 | D11: 9,3 | E11: 15,8 | F11: 21,1 | G11: 26,6 | H11: 28,2 | I11: 26,4 | J11: 21,1 | K11: 14,6 | L11: 8,6 | M11: 3,2 | N11: 15,0 | O11: =-20.5/1979 -> -0.010358767 | P11: 43.5/1993 | Q11: 34,8 | R11: -2,2
A12: Ангрен | B12: 0,9 | C12: 2,3 | D12: 7,4 | E12: 13,6 | F12: 18,5 | G12: 23,7 | H12: 25,8 | I12: 24,5 | J12: 19,5 | K12: 12,8 | L12: 7,7 | M12: 2,9 | N12: 13,3 | O12: =-27/1935 -> -0.013953488 | P12: 42.6/1944 | Q12: 32,1 | R12: -2,7
A13: Бошқизилсой | B13: -0,4 | C13: 0,9 | D13: 5,4 | E13: 11,4 | F13: 15,9 | G13: 21,1 | H13: 23,6 | I13: 22,6 | J13: 17,5 | K13: 10,9 | L13: 6,1 | M13: 1,6 | N13: 11,4 | O13: =-29.7/1969 -> -0.015083799 | P13: 40.0/1984 | Q13: 30,0 | R13: -3,4
A14: Сўқоқ | B14: 0,1 | C14: 1,0 | D14: 5,1 | E14: 11,2 | F14: 15,7 | G14: 21,0 | H14: 23,2 | I14: 22,4 | J14: 17,6 | K14: 11,4 | L14: 6,6 | M14: 2,3 | N14: 11,5 | O14: =-25.4/1974 -> -0.012867275 | P14: 37.2/1983 | Q14: 28,6 | R14: -3,3
A15: Дукент | B15: -2,9 | C15: -2,4 | D15: 1,5 | E15: 7,5 | F15: 11,9 | G15: 17,0 | H15: 19,6 | I15: 19,2 | J15: 14,7 | K15: 8,3 | L15: 3,6 | M15: -0,6 | N15: 8,1 | O15: =-24.5/1969 -> -0.012442864 | P15: 35.2/1983,2008 | Q15: 25,4 | R15: -5,9
A16: Чимён | B16: -2,9 | C16: -2,1 | D16: 2,0 | E16: 8,4 | F16: 13,1 | G16: 18,3 | H16: 20,8 | I16: 20,4 | J16: 15,5 | K16: 9,0 | L16: 4,0 | M16: -0,6 | N16: 8,8 | O16: =-23/1941 -> -0.011849562 | P16: 35.2/2008 | Q16: 26,1 | R16: -6,0
A17: Пскем | B17: -2,9 | C17: -1,7 | D17: 3,2 | E17: 10,1 | F17: 14,3 | G17: 18,8 | H17: 21,8 | I17: 21,7 | J17: 16,8 | K17: 9,9 | L17: 4,5 | M17: -0,7 | N17: 9,7 | O17: =-26.9/1943 -> -0.01384457 | P17: 41.7/1983 | Q17: 29,8 | R17: -6,5
A18: Ойгаинг | B18: -9,8 | C18: -8,8 | D18: -4,3 | E18: 1,5 | F18: 7,7 | G18: 12,2 | H18: 14,9 | I18: 15,3 | J18: 10,6 | K18: 3,4 | L18: -2,9 | M18: -7,7 | N18: 2,7 | O18: =-31.6/1969 -> -0.016048756 | P18: 36.0/1976 | Q18: 23,2 | R18: -14,1

Sheet Building_data
B3: Description | C3: Unit | D3: Value
B4: Total net heated floor area | C4: [m²] | D4: =Envelope!L95 -> 2515.415
B5: Total net heated volume | C5: [m³] | D5: =Envelope!M95 -> 7546.245
B6: Total net cooled floor area (if any) | C6: [m²] | D6: 0
B7: Duration of the heating season (as per NCM M.01.02:2016, Annex A) | C7: [days] | D7: 163
B8: Average inside temperature during heating season in non-operation hours (standardized) | C8: [°C] | D8: 14
B9: Average inside temperature during heating season in operation hours (standardized) | C9: [°C] | D9: 22
B10: Medium outside temperature during heating season (as per NCM M.01.02:2016, Annex A) | C10: [°C] | D10: 3.9
B11: Coldest 5 days outside temperature (design temperature, as per СНиП 2.01.01-82) | C11: [°C] | D11: -14
B12: Operation hours during heating season | C12: [h/y] | D12: =D14*D7 -> 1630
B13: Non-operation hours during heating season | C13: [h/y] | D13: 14
B14: Operation hours per day | C14: [h/d] | D14: 10
B15: Average inside enthalpy during cooling period for +24°C and relative humidity of 50% | C15: [kJ/kg] | D15: 48.4
B16: Average outside enthalpy during cooling period | C16: [kJ/kg] | D16: 59.5
B17: Outside enthalpy during the hottest summer day | C17: [kJ/kg] | D17: 69.13
B18: Average number of people inside the building | C18: [No of people] | D18: =360+58 -> 418

Sheet Envelope
B4: Block | C4: Orientation | D4: Side of the building | E4: Element | F4: Walls | L4: Windows | U4: Doors
F5: Dimension | I5: Area | L5: Dimension | N5: Type | Q5: Area | T5: Perimeter of window sills [m] | U5: Dimension | W5: Type | Z5: Area | AC5: Perimeter of door sills [m]
F6: Lenght [m] | G6: Height of the wall in contact with environment [m] | H6: Height of the wall in contact with the ground [m] | I6: Brut area of the wall in contact with environment [m2] | J6: Area of the wall in contact with the ground [m2] | K6: Net area of the wall in contact with environment [m2] | L6: Lenght [m] | M6: Height [m] | N6: Win 1 [units] | O6: Win 2 [units] | P6: Win 3 [units] | Q6: Win 1 [m2] | R6: Win 2 [m2] | S6: Win 3 [m2] | U6: Lenght [m] | V6: Height [m] | W6: D 1 [units] | X6: D 2 [units] | Y6: D 3 [units] | Z6: D 1 [m2] | AA6: D 2 [m2] | AB6: D 3 [m2] | AD6: =SUM(AD7:AD73) -> 256.62
B7: 3-DMTT | C7: N | D7: P1 | E7: W1 | F7: 50.7 | G7: =3.3*2 -> 6.6 | I7: =F7*G7 -> 334.62 | J7: =F7*H7 -> 0 | K7: =I7-Q7-R7-S7-Z7-AA7-AB7 -> 277.82 | L7: 1.2 | M7: 1.8 | P7: 21 | Q7: =L7*M7*N7 -> 0 | R7: =L7*M7*O7 -> 0 | S7: =L7*M7*P7 -> 45.36 | T7: =((L7+M7)*2)*(N7+O7+P7) -> 126 | U7: 2.2 | V7: 2.6 | W7: 2 | Z7: =U7*V7*W7 -> 11.44 | AA7: =U7*V7*X7 -> 0 | AB7: =U7*V7*Y7 -> 0 | AC7: =((U7+V7)*2)*(W7+X7+Y7) -> 19.2 | AD7: =SUM(Q7:S7) -> 45.36 | AE7: S | AF7: =SUMIF($C$7:$C$73,AE7,$AD$7:$AD$73) -> 79.02
E8: Socle 1. (unheated space) | F8: 50.7 | G8: 0.55 | I8: =F8*G8 -> 27.885 | J8: =F8*H8 -> 0 | K8: =I8-Q8-R8-S8-Z8-AA8-AB8 -> 22.485 | L8: 1 | M8: 1.8 | P8: 1 | Q8: =L8*M8*N8 -> 0 | R8: =L8*M8*O8 -> 0 | S8: =L8*M8*P8 -> 1.8 | T8: =((L8+M8)*2)*(N8+O8+P8) -> 5.6 | U8: 0.9 | V8: 2 | W8: 2 | Z8: =U8*V8*W8 -> 3.6 | AA8: =U8*V8*X8 -> 0 | AB8: =U8*V8*Y8 -> 0 | AC8: =((U8+V8)*2)*(W8+X8+Y8) -> 11.6 | AD8: =SUM(Q8:S8) -> 1.8 | AE8: N | AF8: =SUMIF($C$7:$C$73,AE8,$AD$7:$AD$73) -> 86.4
I9: =F9*G9 -> 0 | J9: =F9*H9 -> 0 | K9: =I9-Q9-R9-S9-Z9-AA9-AB9 -> -2.56 | L9: 0.8 | M9: 0.8 | P9: 4 | Q9: =L9*M9*N9 -> 0 | R9: =L9*M9*O9 -> 0 | S9: =L9*M9*P9 -> 2.56 | T9: =((L9+M9)*2)*(N9+O9+P9) -> 12.8 | Z9: =U9*V9*W9 -> 0 | AA9: =U9*V9*X9 -> 0 | AB9: =U9*V9*Y9 -> 0 | AC9: =((U9+V9)*2)*(W9+X9+Y9) -> 0 | AD9: =SUM(Q9:S9) -> 2.56 | AE9: E | AF9: =SUMIF($C$7:$C$73,AE9,$AD$7:$AD$73) -> 10.8
C10: W | D10: P2 | E10: W1 | F10: 13.2 | G10: =3.3*2 -> 6.6 | I10: =F10*G10 -> 87.12 | J10: =F10*H10 -> 0 | K10: =I10-Q10-R10-S10-Z10-AA10-AB10 -> 75.24 | L10: 1.2 | M10: 1.8 | P10: 3 | Q10: =L10*M10*N10 -> 0 | R10: =L10*M10*O10 -> 0 | S10: =L10*M10*P10 -> 6.48 | T10: =((L10+M10)*2)*(N10+O10+P10) -> 18 | U10: 0.9 | V10: 2 | W10: 3 | Z10: =U10*V10*W10 -> 5.4 | AA10: =U10*V10*X10 -> 0 | AB10: =U10*V10*Y10 -> 0 | AC10: =((U10+V10)*2)*(W10+X10+Y10) -> 17.4 | AD10: =SUM(Q10:S10) -> 6.48 | AE10: W | AF10: =SUMIF($C$7:$C$73,AE10,$AD$7:$AD$73) -> 14.76
E11: Socle 1. (unheated space) | F11: 13.2 | G11: 0.55 | I11: =F11*G11 -> 7.26 | J11: =F11*H11 -> 0 | K11: =I11-Q11-R11-S11-Z11-AA11-AB11 -> 0.06 | L11: 1 | M11: 1.8 | P11: 4 | Q11: =L11*M11*N11 -> 0 | R11: =L11*M11*O11 -> 0 | S11: =L11*M11*P11 -> 7.2 | T11: =((L11+M11)*2)*(N11+O11+P11) -> 22.4 | Z11: =U11*V11*W11 -> 0 | AA11: =U11*V11*X11 -> 0 | AB11: =U11*V11*Y11 -> 0 | AC11: =((U11+V11)*2)*(W11+X11+Y11) -> 0 | AD11: =SUM(Q11:S11) -> 7.2 | AE11: SW | AF11: =SUMIF($C$7:$C$73,AE11,$AD$7:$AD$73) -> 0
C12: S | D12: P3 | E12: W1 | F12: 24.5 | G12: 6.6 | I12: =F12*G12 -> 161.7 | J12: =F12*H12 -> 0 | K12: =I12-Q12-R12-S12-Z12-AA12-AB12 -> 135.78 | L12: 1.2 | M12: 1.8 | P12: 12 | Q12: =L12*M12*N12 -> 0 | R12: =L12*M12*O12 -> 0 | S12: =L12*M12*P12 -> 25.92 | T12: =((L12+M12)*2)*(N12+O12+P12) -> 72 | Z12: =U12*V12*W12 -> 0 | AA12: =U12*V12*X12 -> 0 | AB12: =U12*V12*Y12 -> 0 | AC12: =((U12+V12)*2)*(W12+X12+Y12) -> 0 | AD12: =SUM(Q12:S12) -> 25.92 | AE12: SE | AF12: =SUMIF($C$7:$C$73,AE12,$AD$7:$AD$73) -> 0
E13: Socle 1. (unheated space) | F13: 24.5 | G13: 0.55 | I13: =F13*G13 -> 13.475 | J13: =F13*H13 -> 0 | K13: =I13-Q13-R13-S13-Z13-AA13-AB13 -> 12.195 | L13: 0.8 | M13: 0.8 | P13: 2 | Q13: =L13*M13*N13 -> 0 | R13: =L13*M13*O13 -> 0 | S13: =L13*M13*P13 -> 1.28 | T13: =((L13+M13)*2)*(N13+O13+P13) -> 6.4 | Z13: =U13*V13*W13 -> 0 | AA13: =U13*V13*X13 -> 0 | AB13: =U13*V13*Y13 -> 0 | AC13: =((U13+V13)*2)*(W13+X13+Y13) -> 0 | AD13: =SUM(Q13:S13) -> 1.28 | AE13: NE | AF13: =SUMIF($C$7:$C$73,AE13,$AD$7:$AD$73) -> 0
C14: W | D14: P4 | E14: W1 | F14: 13.25 | G14: 3.3 | I14: =F14*G14 -> 43.725 | J14: =F14*H14 -> 0 | K14: =I14-Q14-R14-S14-Z14-AA14-AB14 -> 40.125 | L14: 1 | M14: 1.8 | P14: 1 | Q14: =L14*M14*N14 -> 0 | R14: =L14*M14*O14 -> 0 | S14: =L14*M14*P14 -> 1.8 | T14: =((L14+M14)*2)*(N14+O14+P14) -> 5.6 | U14: 0.9 | V14: 2 | W14: 1 | Z14: =U14*V14*W14 -> 1.8 | AA14: =U14*V14*X14 -> 0 | AB14: =U14*V14*Y14 -> 0 | AC14: =((U14+V14)*2)*(W14+X14+Y14) -> 5.8 | AD14: =SUM(Q14:S14) -> 1.8 | AE14: NW | AF14: =SUMIF($C$7:$C$73,AE14,$AD$7:$AD$73) -> 0
E15: Socle 1. (unheated space) | F15: 13.25 | G15: 0.55 | I15: =F15*G15 -> 7.2875 | J15: =F15*H15 -> 0 | K15: =I15-Q15-R15-S15-Z15-AA15-AB15 -> 7.2875 | Q15: =L15*M15*N15 -> 0 | R15: =L15*M15*O15 -> 0 | S15: =L15*M15*P15 -> 0 | T15: =((L15+M15)*2)*(N15+O15+P15) -> 0 | Z15: =U15*V15*W15 -> 0 | AA15: =U15*V15*X15 -> 0 | AB15: =U15*V15*Y15 -> 0 | AC15: =((U15+V15)*2)*(W15+X15+Y15) -> 0 | AD15: =SUM(Q15:S15) -> 0
I16: =F16*G16 -> 0 | J16: =F16*H16 -> 0 | K16: =I16-Q16-R16-S16-Z16-AA16-AB16 -> 0 | Q16: =L16*M16*N16 -> 0 | R16: =L16*M16*O16 -> 0 | S16: =L16*M16*P16 -> 0 | T16: =((L16+M16)*2)*(N16+O16+P16) -> 0 | Z16: =U16*V16*W16 -> 0 | AA16: =U16*V16*X16 -> 0 | AB16: =U16*V16*Y16 -> 0 | AC16: =((U16+V16)*2)*(W16+X16+Y16) -> 0 | AD16: =SUM(Q16:S16) -> 0
I17: =F17*G17 -> 0 | J17: =F17*H17 -> 0 | K17: =I17-Q17-R17-S17-Z17-AA17-AB17 -> 0 | Q17: =L17*M17*N17 -> 0 | R17: =L17*M17*O17 -> 0 | S17: =L17*M17*P17 -> 0 | T17: =((L17+M17)*2)*(N17+O17+P17) -> 0 | Z17: =U17*V17*W17 -> 0 | AA17: =U17*V17*X17 -> 0 | AB17: =U17*V17*Y17 -> 0 | AC17: =((U17+V17)*2)*(W17+X17+Y17) -> 0 | AD17: =SUM(Q17:S17) -> 0
I18: =F18*G18 -> 0 | J18: =F18*H18 -> 0 | K18: =I18-Q18-R18-S18-Z18-AA18-AB18 -> 0 | Q18: =L18*M18*N18 -> 0 | R18: =L18*M18*O18 -> 0 | S18: =L18*M18*P18 -> 0 | T18: =((L18+M18)*2)*(N18+O18+P18) -> 0 | Z18: =U18*V18*W18 -> 0 | AA18: =U18*V18*X18 -> 0 | AB18: =U18*V18*Y18 -> 0 | AC18: =((U18+V18)*2)*(W18+X18+Y18) -> 0 | AD18: =SUM(Q18:S18) -> 0
C19: N | D19: P5 | E19: W1 | F19: 24.5 | G19: 6.6 | I19: =F19*G19 -> 161.7 | J19: =F19*H19 -> 0 | K19: =I19-Q19-R19-S19-Z19-AA19-AB19 -> 135.78 | L19: 1.2 | M19: 1.8 | P19: 12 | Q19: =L19*M19*N19 -> 0 | R19: =L19*M19*O19 -> 0 | S19: =L19*M19*P19 -> 25.92 | T19: =((L19+M19)*2)*(N19+O19+P19) -> 72 | Z19: =U19*V19*W19 -> 0 | AA19: =U19*V19*X19 -> 0 | AB19: =U19*V19*Y19 -> 0 | AC19: =((U19+V19)*2)*(W19+X19+Y19) -> 0 | AD19: =SUM(Q19:S19) -> 25.92
E20: Socle 1. (unheated space) | F20: 24.5 | G20: 0.55 | I20: =F20*G20 -> 13.475 | J20: =F20*H20 -> 0 | K20: =I20-Q20-R20-S20-Z20-AA20-AB20 -> 12.195 | L20: 0.8 | M20: 0.8 | P20: 2 | Q20: =L20*M20*N20 -> 0 | R20: =L20*M20*O20 -> 0 | S20: =L20*M20*P20 -> 1.28 | T20: =((L20+M20)*2)*(N20+O20+P20) -> 6.4 | Z20: =U20*V20*W20 -> 0 | AA20: =U20*V20*X20 -> 0 | AB20: =U20*V20*Y20 -> 0 | AC20: =((U20+V20)*2)*(W20+X20+Y20) -> 0 | AD20: =SUM(Q20:S20) -> 1.28
I21: =F21*G21 -> 0 | J21: =F21*H21 -> 0 | K21: =I21-Q21-R21-S21-Z21-AA21-AB21 -> 0 | Q21: =L21*M21*N21 -> 0 | R21: =L21*M21*O21 -> 0 | S21: =L21*M21*P21 -> 0 | T21: =((L21+M21)*2)*(N21+O21+P21) -> 0 | Z21: =U21*V21*W21 -> 0 | AA21: =U21*V21*X21 -> 0 | AB21: =U21*V21*Y21 -> 0 | AC21: =((U21+V21)*2)*(W21+X21+Y21) -> 0 | AD21: =SUM(Q21:S21) -> 0
Q22: =L22*M22*N22 -> 0 | R22: =L22*M22*O22 -> 0 | S22: =L22*M22*P22 -> 0 | T22: =((L22+M22)*2)*(N22+O22+P22) -> 0 | Z22: =U22*V22*W22 -> 0 | AA22: =U22*V22*X22 -> 0 | AB22: =U22*V22*Y22 -> 0 | AC22: =((U22+V22)*2)*(W22+X22+Y22) -> 0 | AD22: =SUM(Q22:S22) -> 0
Q23: =L23*M23*N23 -> 0 | R23: =L23*M23*O23 -> 0 | S23: =L23*M23*P23 -> 0 | T23: =((L23+M23)*2)*(N23+O23+P23) -> 0 | Z23: =U23*V23*W23 -> 0 | AA23: =U23*V23*X23 -> 0 | AB23: =U23*V23*Y23 -> 0 | AC23: =((U23+V23)*2)*(W23+X23+Y23) -> 0 | AD23: =SUM(Q23:S23) -> 0
C24: W | D24: P6 | E24: W1 | F24: 13.2 | G24: 6.6 | I24: =F24*G24 -> 87.12 | J24: =F24*H24 -> 0 | K24: =I24-Q24-R24-S24-Z24-AA24-AB24 -> 75.24 | L24: 1.2 | M24: 1.8 | P24: 3 | Q24: =L24*M24*N24 -> 0 | R24: =L24*M24*O24 -> 0 | S24: =L24*M24*P24 -> 6.48 | T24: =((L24+M24)*2)*(N24+O24+P24) -> 18 | U24: 0.9 | V24: 2 | W24: 3 | Z24: =U24*V24*W24 -> 5.4 | AA24: =U24*V24*X24 -> 0 | AB24: =U24*V24*Y24 -> 0 | AC24: =((U24+V24)*2)*(W24+X24+Y24) -> 17.4 | AD24: =SUM(Q24:S24) -> 6.48
E25: Socle 1. (unheated space) | F25: 13.2 | G25: 0.55 | I25: =F25*G25 -> 7.26 | J25: =F25*H25 -> 0 | K25: =I25-Q25-R25-S25-Z25-AA25-AB25 -> -1.74 | L25: 1 | M25: 1.8 | P25: 5 | Q25: =L25*M25*N25 -> 0 | R25: =L25*M25*O25 -> 0 | S25: =L25*M25*P25 -> 9 | T25: =((L25+M25)*2)*(N25+O25+P25) -> 28 | Z25: =U25*V25*W25 -> 0 | AA25: =U25*V25*X25 -> 0 | AB25: =U25*V25*Y25 -> 0 | AC25: =((U25+V25)*2)*(W25+X25+Y25) -> 0 | AD25: =SUM(Q25:S25) -> 9
I26: =F26*G26 -> 0 | J26: =F26*H26 -> 0 | K26: =I26-Q26-R26-S26-Z26-AA26-AB26 -> 0 | Q26: =L26*M26*N26 -> 0 | R26: =L26*M26*O26 -> 0 | S26: =L26*M26*P26 -> 0 | T26: =((L26+M26)*2)*(N26+O26+P26) -> 0 | Z26: =U26*V26*W26 -> 0 | AA26: =U26*V26*X26 -> 0 | AB26: =U26*V26*Y26 -> 0 | AC26: =((U26+V26)*2)*(W26+X26+Y26) -> 0 | AD26: =SUM(Q26:S26) -> 0
C27: S | D27: P7 | E27: W1 | F27: 50.7 | G27: 6.6 | I27: =F27*G27 -> 334.62 | J27: =F27*H27 -> 0 | K27: =I27-Q27-R27-S27-Z27-AA27-AB27 -> 275.66 | L27: 1.2 | M27: 1.8 | P27: 22 | Q27: =L27*M27*N27 -> 0 | R27: =L27*M27*O27 -> 0 | S27: =L27*M27*P27 -> 47.52 | T27: =((L27+M27)*2)*(N27+O27+P27) -> 132 | U27: 2.2 | V27: 2.6 | W27: 2 | Z27: =U27*V27*W27 -> 11.44 | AA27: =U27*V27*X27 -> 0 | AB27: =U27*V27*Y27 -> 0 | AC27: =((U27+V27)*2)*(W27+X27+Y27) -> 19.2 | AD27: =SUM(Q27:S27) -> 47.52
E28: Socle 1. (unheated space) | F28: 50.7 | G28: 0.55 | I28: =F28*G28 -> 27.885 | J28: =F28*H28 -> 0 | K28: =I28-Q28-R28-S28-Z28-AA28-AB28 -> 21.725 | L28: 0.8 | M28: 0.8 | P28: 4 | Q28: =L28*M28*N28 -> 0 | R28: =L28*M28*O28 -> 0 | S28: =L28*M28*P28 -> 2.56 | T28: =((L28+M28)*2)*(N28+O28+P28) -> 12.8 | U28: 0.9 | V28: 2 | W28: 2 | Z28: =U28*V28*W28 -> 3.6 | AA28: =U28*V28*X28 -> 0 | AB28: =U28*V28*Y28 -> 0 | AC28: =((U28+V28)*2)*(W28+X28+Y28) -> 11.6 | AD28: =SUM(Q28:S28) -> 2.56
I29: =F29*G29 -> 0 | J29: =F29*H29 -> 0 | K29: =I29-Q29-R29-S29-Z29-AA29-AB29 -> 0 | Q29: =L29*M29*N29 -> 0 | R29: =L29*M29*O29 -> 0 | S29: =L29*M29*P29 -> 0 | T29: =((L29+M29)*2)*(N29+O29+P29) -> 0 | Z29: =U29*V29*W29 -> 0 | AA29: =U29*V29*X29 -> 0 | AB29: =U29*V29*Y29 -> 0 | AC29: =((U29+V29)*2)*(W29+X29+Y29) -> 0 | AD29: =SUM(Q29:S29) -> 0
I30: =F30*G30 -> 0 | J30: =F30*H30 -> 0 | K30: =I30-Q30-R30-S30-Z30-AA30-AB30 -> 0 | Q30: =L30*M30*N30 -> 0 | R30: =L30*M30*O30 -> 0 | S30: =L30*M30*P30 -> 0 | T30: =((L30+M30)*2)*(N30+O30+P30) -> 0 | Z30: =U30*V30*W30 -> 0 | AA30: =U30*V30*X30 -> 0 | AB30: =U30*V30*Y30 -> 0 | AC30: =((U30+V30)*2)*(W30+X30+Y30) -> 0 | AD30: =SUM(Q30:S30) -> 0
I31: =F31*G31 -> 0 | J31: =F31*H31 -> 0 | K31: =I31-Q31-R31-S31-Z31-AA31-AB31 -> 0 | Q31: =L31*M31*N31 -> 0 | R31: =L31*M31*O31 -> 0 | S31: =L31*M31*P31 -> 0 | T31: =((L31+M31)*2)*(N31+O31+P31) -> 0 | Z31: =U31*V31*W31 -> 0 | AA31: =U31*V31*X31 -> 0 | AB31: =U31*V31*Y31 -> 0 | AC31: =((U31+V31)*2)*(W31+X31+Y31) -> 0 | AD31: =SUM(Q31:S31) -> 0
C32: E | D32: P8 | E32: W1 | F32: 13.2 | G32: 6.6 | I32: =F32*G32 -> 87.12 | J32: =F32*H32 -> 0 | K32: =I32-Q32-R32-S32-Z32-AA32-AB32 -> 79.2 | L32: 1.2 | M32: 1.8 | P32: 2 | Q32: =L32*M32*N32 -> 0 | R32: =L32*M32*O32 -> 0 | S32: =L32*M32*P32 -> 4.32 | T32: =((L32+M32)*2)*(N32+O32+P32) -> 12 | U32: 0.9 | V32: 2 | W32: 2 | Z32: =U32*V32*W32 -> 3.6 | AA32: =U32*V32*X32 -> 0 | AB32: =U32*V32*Y32 -> 0 | AC32: =((U32+V32)*2)*(W32+X32+Y32) -> 11.6 | AD32: =SUM(Q32:S32) -> 4.32
E33: Socle 1. (unheated space) | F33: 13.2 | G33: 0.55 | I33: =F33*G33 -> 7.26 | J33: =F33*H33 -> 0 | K33: =I33-Q33-R33-S33-Z33-AA33-AB33 -> 0.06 | L33: 1 | M33: 1.8 | P33: 4 | Q33: =L33*M33*N33 -> 0 | R33: =L33*M33*O33 -> 0 | S33: =L33*M33*P33 -> 7.2 | T33: =((L33+M33)*2)*(N33+O33+P33) -> 22.4 | Z33: =U33*V33*W33 -> 0 | AA33: =U33*V33*X33 -> 0 | AB33: =U33*V33*Y33 -> 0 | AC33: =((U33+V33)*2)*(W33+X33+Y33) -> 0 | AD33: =SUM(Q33:S33) -> 7.2
I34: =F34*G34 -> 0 | J34: =F34*H34 -> 0 | K34: =I34-Q34-R34-S34-Z34-AA34-AB34 -> 0 | Q34: =L34*M34*N34 -> 0 | R34: =L34*M34*O34 -> 0 | S34: =L34*M34*P34 -> 0 | T34: =((L34+M34)*2)*(N34+O34+P34) -> 0 | Z34: =U34*V34*W34 -> 0 | AA34: =U34*V34*X34 -> 0 | AB34: =U34*V34*Y34 -> 0 | AC34: =((U34+V34)*2)*(W34+X34+Y34) -> 0 | AD34: =SUM(Q34:S34) -> 0
C35: N | D35: P9 | E35: W1 | F35: 21.3 | G35: 6.6 | I35: =F35*G35 -> 140.58 | J35: =F35*H35 -> 0 | K35: =I35-Q35-R35-S35-Z35-AA35-AB35 -> 125.82 | L35: 1.2 | M35: 1.8 | P35: 6 | Q35: =L35*M35*N35 -> 0 | R35: =L35*M35*O35 -> 0 | S35: =L35*M35*P35 -> 12.96 | T35: =((L35+M35)*2)*(N35+O35+P35) -> 36 | U35: 0.9 | V35: 2 | W35: 1 | Z35: =U35*V35*W35 -> 1.8 | AA35: =U35*V35*X35 -> 0 | AB35: =U35*V35*Y35 -> 0 | AC35: =((U35+V35)*2)*(W35+X35+Y35) -> 5.8 | AD35: =SUM(Q35:S35) -> 12.96
E36: Socle 1. (unheated space) | F36: 21.3 | G36: 0.55 | I36: =F36*G36 -> 11.715 | J36: =F36*H36 -> 0 | K36: =I36-Q36-R36-S36-Z36-AA36-AB36 -> 9.915 | L36: 1 | M36: 1.8 | P36: 1 | Q36: =L36*M36*N36 -> 0 | R36: =L36*M36*O36 -> 0 | S36: =L36*M36*P36 -> 1.8 | T36: =((L36+M36)*2)*(N36+O36+P36) -> 5.6 | Z36: =U36*V36*W36 -> 0 | AA36: =U36*V36*X36 -> 0 | AB36: =U36*V36*Y36 -> 0 | AC36: =((U36+V36)*2)*(W36+X36+Y36) -> 0 | AD36: =SUM(Q36:S36) -> 1.8
I37: =F37*G37 -> 0 | J37: =F37*H37 -> 0 | K37: =I37-Q37-R37-S37-Z37-AA37-AB37 -> 0 | Q37: =L37*M37*N37 -> 0 | R37: =L37*M37*O37 -> 0 | S37: =L37*M37*P37 -> 0 | T37: =((L37+M37)*2)*(N37+O37+P37) -> 0 | Z37: =U37*V37*W37 -> 0 | AA37: =U37*V37*X37 -> 0 | AB37: =U37*V37*Y37 -> 0 | AC37: =((U37+V37)*2)*(W37+X37+Y37) -> 0 | AD37: =SUM(Q37:S37) -> 0
I38: =F38*G38 -> 0 | J38: =F38*H38 -> 0 | K38: =I38-Q38-R38-S38-Z38-AA38-AB38 -> 0 | Q38: =L38*M38*N38 -> 0 | R38: =L38*M38*O38 -> 0 | S38: =L38*M38*P38 -> 0 | T38: =((L38+M38)*2)*(N38+O38+P38) -> 0 | Z38: =U38*V38*W38 -> 0 | AA38: =U38*V38*X38 -> 0 | AB38: =U38*V38*Y38 -> 0 | AC38: =((U38+V38)*2)*(W38+X38+Y38) -> 0 | AD38: =SUM(Q38:S38) -> 0
C39: E | D39: P10 | E39: W1 | F39: 13.25 | G39: 3.3 | I39: =F39*G39 -> 43.725 | J39: =F39*H39 -> 0 | K39: =I39-Q39-R39-S39-Z39-AA39-AB39 -> 39.375 | Q39: =L39*M39*N39 -> 0 | R39: =L39*M39*O39 -> 0 | S39: =L39*M39*P39 -> 0 | T39: =((L39+M39)*2)*(N39+O39+P39) -> 0 | U39: 1.5 | V39: 2.9 | W39: 1 | Z39: =U39*V39*W39 -> 4.35 | AA39: =U39*V39*X39 -> 0 | AB39: =U39*V39*Y39 -> 0 | AC39: =((U39+V39)*2)*(W39+X39+Y39) -> 8.8 | AD39: =SUM(Q39:S39) -> 0
E40: Socle 1. (unheated space) | F40: 13.25 | G40: 0.55 | I40: =F40*G40 -> 7.2875 | J40: =F40*H40 -> 0 | K40: =I40-Q40-R40-S40-Z40-AA40-AB40 -> 7.2875 | Q40: =L40*M40*N40 -> 0 | R40: =L40*M40*O40 -> 0 | S40: =L40*M40*P40 -> 0 | T40: =((L40+M40)*2)*(N40+O40+P40) -> 0 | Z40: =U40*V40*W40 -> 0 | AA40: =U40*V40*X40 -> 0 | AB40: =U40*V40*Y40 -> 0 | AC40: =((U40+V40)*2)*(W40+X40+Y40) -> 0 | AD40: =SUM(Q40:S40) -> 0
I41: =F41*G41 -> 0 | J41: =F41*H41 -> 0 | K41: =I41-Q41-R41-S41-Z41-AA41-AB41 -> 0 | Q41: =L41*M41*N41 -> 0 | R41: =L41*M41*O41 -> 0 | S41: =L41*M41*P41 -> 0 | T41: =((L41+M41)*2)*(N41+O41+P41) -> 0 | Z41: =U41*V41*W41 -> 0 | AA41: =U41*V41*X41 -> 0 | AB41: =U41*V41*Y41 -> 0 | AC41: =((U41+V41)*2)*(W41+X41+Y41) -> 0 | AD41: =SUM(Q41:S41) -> 0
I42: =F42*G42 -> 0 | J42: =F42*H42 -> 0 | K42: =I42-Q42-R42-S42-Z42-AA42-AB42 -> 0 | Q42: =L42*M42*N42 -> 0 | R42: =L42*M42*O42 -> 0 | S42: =L42*M42*P42 -> 0 | T42: =((L42+M42)*2)*(N42+O42+P42) -> 0 | Z42: =U42*V42*W42 -> 0 | AA42: =U42*V42*X42 -> 0 | AB42: =U42*V42*Y42 -> 0 | AC42: =((U42+V42)*2)*(W42+X42+Y42) -> 0 | AD42: =SUM(Q42:S42) -> 0
C43: S | D43: P11 | E43: W1 | F43: =10.3+11 -> 21.3 | G43: 6.6 | I43: =F43*G43 -> 140.58 | J43: =F43*H43 -> 0 | K43: =I43-Q43-R43-S43-Z43-AA43-AB43 -> 133.56 | L43: 1.9 | M43: 1.8 | P43: 1 | Q43: =L43*M43*N43 -> 0 | R43: =L43*M43*O43 -> 0 | S43: =L43*M43*P43 -> 3.42 | T43: =((L43+M43)*2)*(N43+O43+P43) -> 7.4 | U43: 0.9 | V43: 2 | W43: 2 | Z43: =U43*V43*W43 -> 3.6 | AA43: =U43*V43*X43 -> 0 | AB43: =U43*V43*Y43 -> 0 | AC43: =((U43+V43)*2)*(W43+X43+Y43) -> 11.6 | AD43: =SUM(Q43:S43) -> 3.42
...

Sheet Consumption
B4: GAS | D4: Anul 2023 | G4: Anul 2024 | J4: Anul 2025 | M4: Average for the past 3 years (Baseline)
B5: № | C5: Davr | D5: Consum | E5: Expenses | F5: Tarif [so'm/m3] | G5: Consum | H5: Expenses | I5: Tarif [so'm/m3] | J5: Consum | K5: Expenses | L5: Tarif [so'm/m3] | M5: Consum | N5: Expenses | O5: Tarif [so'm/m3] | R5: According to latest tariff | U5: =Measures_summary!D45 -> 700000 | V5: so'm/gcal
D6: [m3] | E6: [so'm] | G6: [m3] | H6: [so'm] | J6: [m3] | K6: [so'm] | M6: [kWh] | N6: [so'm] | S6: Thermal | U6: =U5/1163 -> 601.89166 | V6: so'm/kWh
B7: 1 | C7: January | D7: 7274 | E7: =D7*F7 -> 18185000 | F7: =$U$8 -> 2500 | G7: 5691 | H7: =G7*I7 -> 14227500 | I7: =$U$8 -> 2500 | J7: 6976 | K7: =J7*L7 -> 17440000 | L7: =$U$8 -> 2500 | M7: =(D7+G7+J7)*9.5/3 -> 63146.5 | N7: =M7*O7 -> 69461150 | O7: 1100 | S7: Electrical | U7: =Measures_summary!D46 -> 1100 | V7: so'm/kWh | X7: 8887
B8: 2 | C8: February | D8: 5399 | E8: =D8*F8 -> 13497500 | F8: =$U$8 -> 2500 | G8: 5304 | H8: =G8*I8 -> 13260000 | I8: =$U$8 -> 2500 | J8: 5774 | K8: =J8*L8 -> 14435000 | L8: =$U$8 -> 2500 | M8: =(D8+G8+J8)*9.5/3 -> 52177.167 | N8: =M8*O8 -> 57394883 | O8: 1100 | S8: GAS | U8: =Measures_summary!D47 -> 2500 | V8: so'm/m3
B9: 3 | C9: March | D9: 1710 | E9: =D9*F9 -> 4275000 | F9: =$U$8 -> 2500 | G9: 3218 | H9: =G9*I9 -> 8045000 | I9: =$U$8 -> 2500 | J9: 2989 | K9: =J9*L9 -> 7472500 | L9: =$U$8 -> 2500 | M9: =(D9+G9+J9)*9.5/3 -> 25070.5 | N9: =M9*O9 -> 27577550 | O9: 1100
B10: 4 | C10: April | D10: 645 | E10: =D10*F10 -> 1612500 | F10: =$U$8 -> 2500 | G10: 514 | H10: =G10*I10 -> 1285000 | I10: =$U$8 -> 2500 | J10: 79 | K10: =J10*L10 -> 197500 | L10: =$U$8 -> 2500 | M10: =(D10+G10+J10)*9.5/3 -> 3920.3333 | N10: =M10*O10 -> 4312366.7 | O10: 1100
B11: 5 | C11: May | D11: 564 | E11: =D11*F11 -> 1410000 | F11: =$U$8 -> 2500 | G11: 557 | H11: =G11*I11 -> 1392500 | I11: =$U$8 -> 2500 | J11: 66 | K11: =J11*L11 -> 165000 | L11: =$U$8 -> 2500 | M11: =(D11+G11+J11)*9.5/3 -> 3758.8333 | N11: =M11*O11 -> 4134716.7 | O11: 1100
B12: 6 | C12: June | D12: 609 | E12: =D12*F12 -> 1522500 | F12: =$U$8 -> 2500 | G12: 519 | H12: =G12*I12 -> 1297500 | I12: =$U$8 -> 2500 | J12: 54 | K12: =J12*L12 -> 135000 | L12: =$U$8 -> 2500 | M12: =(D12+G12+J12)*9.5/3 -> 3743 | N12: =M12*O12 -> 4117300 | O12: 1100
B13: 7 | C13: July | D13: 614 | E13: =D13*F13 -> 1535000 | F13: =$U$8 -> 2500 | G13: 526 | H13: =G13*I13 -> 1315000 | I13: =$U$8 -> 2500 | J13: 47 | K13: =J13*L13 -> 117500 | L13: =$U$8 -> 2500 | M13: =(D13+G13+J13)*9.5/3 -> 3758.8333 | N13: =M13*O13 -> 4134716.7 | O13: 1100
B14: 8 | C14: August | D14: 571 | E14: =D14*F14 -> 1427500 | F14: =$U$8 -> 2500 | G14: 106 | H14: =G14*I14 -> 265000 | I14: =$U$8 -> 2500 | J14: 1054 | K14: =J14*L14 -> 2635000 | L14: =$U$8 -> 2500 | M14: =(D14+G14+J14)*9.5/3 -> 5481.5 | N14: =M14*O14 -> 6029650 | O14: 1100
B15: 9 | C15: September | D15: 205 | E15: =D15*F15 -> 512500 | F15: =$U$8 -> 2500 | G15: 95 | H15: =G15*I15 -> 237500 | I15: =$U$8 -> 2500 | J15: 62 | K15: =J15*L15 -> 155000 | L15: =$U$8 -> 2500 | M15: =(D15+G15+J15)*9.5/3 -> 1146.3333 | N15: =M15*O15 -> 1260966.7 | O15: 1100
B16: 10 | C16: October | D16: 1138 | E16: =D16*F16 -> 2845000 | F16: =$U$8 -> 2500 | G16: 1062 | H16: =G16*I16 -> 2655000 | I16: =$U$8 -> 2500 | J16: 65 | K16: =J16*L16 -> 162500 | L16: =$U$8 -> 2500 | M16: =(D16+G16+J16)*9.5/3 -> 7172.5 | N16: =M16*O16 -> 7889750 | O16: 1100
B17: 11 | C17: November | D17: 3196 | E17: =D17*F17 -> 7990000 | F17: =$U$8 -> 2500 | G17: 1609 | H17: =G17*I17 -> 4022500 | I17: =$U$8 -> 2500 | J17: 2933 | K17: =J17*L17 -> 7332500 | L17: =$U$8 -> 2500 | M17: =(D17+G17+J17)*9.5/3 -> 24503.667 | N17: =M17*O17 -> 26954033 | O17: 1100
B18: 12 | C18: December | D18: 4965 | E18: =D18*F18 -> 12412500 | F18: =$U$8 -> 2500 | G18: 5476 | H18: =G18*I18 -> 13690000 | I18: =$U$8 -> 2500 | J18: 4239 | K18: =J18*L18 -> 10597500 | L18: =$U$8 -> 2500 | M18: =(D18+G18+J18)*9.5/3 -> 46486.667 | N18: =M18*O18 -> 51135333 | O18: 1100
B19: TOTAL | D19: =SUM(D7:D18) -> 26890 | E19: =SUM(E7:E18) -> 67225000 | G19: =SUM(G7:G18) -> 24677 | H19: =SUM(H7:H18) -> 61692500 | J19: =SUM(J7:J18) -> 24338 | K19: =SUM(K7:K18) -> 60845000 | M19: =SUM(M7:M18) -> 240365.83 | N19: =SUM(N7:N18) -> 2.6440242e+08
B22: Electrical Energy | D22: Anul 2023 | G22: Anul 2024 | J22: Anul 2025 | M22: Average for the past 3 years (Baseline)
B23: № | C23: Davr | D23: Consum | E23: Expenses | F23: Tarif [so'm/kWh] | G23: Consum | H23: Expenses | I23: Tarif [so'm/kWh] | J23: Consum | K23: Expenses | L23: Tarif [so'm/kWh] | M23: Consum | N23: Expenses | O23: Tarif [so'm/kWh]
D24: [kWh] | E24: [so'm] | G24: [kWh] | H24: [so'm] | J24: [kWh] | K24: [so'm] | M24: [kWh] | N24: [so'm]
B25: 1 | C25: January | D25: 4211 | E25: =D25*F25 -> 3789900 | F25: =900 -> 900 | G25: 7119 | H25: =G25*I25 -> 6407100 | I25: =900 -> 900 | J25: 6699 | K25: =J25*L25 -> 6029100 | L25: =900 -> 900 | M25: =(D25+G25+J25)/3 -> 6009.6667 | N25: =M25*O25 -> 6610633.3 | O25: =$U$7 -> 1100
B26: 2 | C26: February | D26: 4389 | E26: =D26*F26 -> 3950100 | F26: =900 -> 900 | G26: 6447 | H26: =G26*I26 -> 5802300 | I26: =900 -> 900 | J26: 5964 | K26: =J26*L26 -> 5367600 | L26: =900 -> 900 | M26: =(D26+G26+J26)/3 -> 5600 | N26: =M26*O26 -> 6160000 | O26: =$U$7 -> 1100
B27: 3 | C27: March | D27: 3633 | E27: =D27*F27 -> 3269700 | F27: =900 -> 900 | G27: 5439 | H27: =G27*I27 -> 4895100 | I27: =900 -> 900 | J27: 4893 | K27: =J27*L27 -> 4403700 | L27: =900 -> 900 | M27: =(D27+G27+J27)/3 -> 4655 | N27: =M27*O27 -> 5120500 | O27: =$U$7 -> 1100
B28: 4 | C28: April | D28: 6111 | E28: =D28*F28 -> 5499900 | F28: =900 -> 900 | G28: 4641 | H28: =G28*I28 -> 4176900 | I28: =900 -> 900 | J28: 4473 | K28: =J28*L28 -> 4025700 | L28: =900 -> 900 | M28: =(D28+G28+J28)/3 -> 5075 | N28: =M28*O28 -> 5582500 | O28: =$U$7 -> 1100
B29: 5 | C29: May | D29: 4095 | E29: =D29*F29 -> 3685500 | F29: =900 -> 900 | G29: 4630 | H29: =G29*I29 -> 4167000 | I29: =900 -> 900 | J29: 4059 | K29: =J29*L29 -> 3653100 | L29: =900 -> 900 | M29: =(D29+G29+J29)/3 -> 4261.3333 | N29: =M29*O29 -> 4687466.7 | O29: =$U$7 -> 1100
B30: 6 | C30: June | D30: 2604 | E30: =D30*F30 -> 2343600 | F30: =900 -> 900 | G30: 3620 | H30: =G30*I30 -> 3258000 | I30: =900 -> 900 | J30: 4000 | K30: =J30*L30 -> 3600000 | L30: =900 -> 900 | M30: =(D30+G30+J30)/3 -> 3408 | N30: =M30*O30 -> 3748800 | O30: =$U$7 -> 1100
B31: 7 | C31: July | D31: 2900 | E31: =D31*F31 -> 2610000 | F31: =900 -> 900 | G31: 3499 | H31: =G31*I31 -> 3149100 | I31: =900 -> 900 | J31: 4138 | K31: =J31*L31 -> 3724200 | L31: =900 -> 900 | M31: =(D31+G31+J31)/3 -> 3512.3333 | N31: =M31*O31 -> 3863566.7 | O31: =$U$7 -> 1100
B32: 8 | C32: August | D32: 2770 | E32: =D32*F32 -> 2493000 | F32: =900 -> 900 | G32: 4157 | H32: =G32*I32 -> 3741300 | I32: =900 -> 900 | J32: 3964 | K32: =J32*L32 -> 3567600 | L32: =900 -> 900 | M32: =(D32+G32+J32)/3 -> 3630.3333 | N32: =M32*O32 -> 3993366.7 | O32: =$U$7 -> 1100
B33: 9 | C33: September | D33: 3780 | E33: =D33*F33 -> 3402000 | F33: =900 -> 900 | G33: 4296 | H33: =G33*I33 -> 3866400 | I33: =900 -> 900 | J33: 3663 | K33: =J33*L33 -> 3296700 | L33: =900 -> 900 | M33: =(D33+G33+J33)/3 -> 3913 | N33: =M33*O33 -> 4304300 | O33: =$U$7 -> 1100
B34: 10 | C34: October | D34: 3507 | E34: =D34*F34 -> 3156300 | F34: =900 -> 900 | G34: 5124 | H34: =G34*I34 -> 4611600 | I34: =900 -> 900 | J34: 4486 | K34: =J34*L34 -> 4037400 | L34: =900 -> 900 | M34: =(D34+G34+J34)/3 -> 4372.3333 | N34: =M34*O34 -> 4809566.7 | O34: =$U$7 -> 1100
B35: 11 | C35: November | D35: 5607 | E35: =D35*F35 -> 5046300 | F35: =900 -> 900 | G35: 5565 | H35: =G35*I35 -> 5008500 | I35: =900 -> 900 | J35: 5751 | K35: =J35*L35 -> 5175900 | L35: =900 -> 900 | M35: =(D35+G35+J35)/3 -> 5641 | N35: =M35*O35 -> 6205100 | O35: =$U$7 -> 1100
B36: 12 | C36: December | D36: 5586 | E36: =D36*F36 -> 5027400 | F36: =900 -> 900 | G36: 6111 | H36: =G36*I36 -> 5499900 | I36: =900 -> 900 | J36: 6204 | K36: =J36*L36 -> 5583600 | L36: =900 -> 900 | M36: =(D36+G36+J36)/3 -> 5967 | N36: =M36*O36 -> 6563700 | O36: =$U$7 -> 1100
B37: TOTAL | D37: =SUM(D25:D36) -> 49193 | E37: =SUM(E25:E36) -> 44273700 | G37: =SUM(G25:G36) -> 60648 | H37: =SUM(H25:H36) -> 54583200 | J37: =SUM(J25:J36) -> 58294 | K37: =SUM(K25:K36) -> 52464600 | M37: =SUM(M25:M36) -> 56045 | N37: =SUM(N25:N36) -> 61649500
B40: Energie Termică | D40: Anul 2023 | G40: Anul 2024 | J40: Anul 2025 | M40: Average for the past 3 years (Baseline)
B41: № | C41: Davr | D41: Consum | E41: Expenses | F41: Tarif [so'm/m3] | G41: Consum | H41: Expenses | I41: Tarif [so'm/m3] | J41: Consum | K41: Expenses | L41: Tarif [so'm/m3] | M41: Consum | N41: Expenses | O41: Tarif [so'm/m3]
D42: [m3] | E42: [so'm] | G42: [m3] | H42: [so'm] | J42: [m3] | K42: [so'm] | M42: [kWh] | N42: [so'm]
B43: 1 | C43: January | F43: 1122 | I43: 1122 | L43: 1122 | M43: =(D43+G43+J43)*1163/3 -> 0 | N43: =M43*O43 -> 0 | O43: =$U$6 -> 601.89166 | X43: 8887
B44: 2 | C44: February | F44: 1122 | I44: 1122 | L44: 1122 | M44: =(D44+G44+J44)*1163/3 -> 0 | N44: =M44*O44 -> 0 | O44: =$U$6 -> 601.89166
B45: 3 | C45: March | F45: 1122 | I45: 1122 | L45: 1122 | M45: =J45*1163 -> 0 | N45: =M45*O45 -> 0 | O45: =$U$6 -> 601.89166
B46: 4 | C46: April | F46: 1122 | I46: 1122 | L46: 1122 | M46: =J46*1163 -> 0 | N46: =M46*O46 -> 0 | O46: =$U$6 -> 601.89166
B47: 5 | C47: May | F47: 1122 | I47: 1122 | L47: 1122 | M47: =J47*1163 -> 0 | N47: =M47*O47 -> 0 | O47: =$U$6 -> 601.89166 | P47: =AA47/Z47 -> #DIV/0! | Q47: =(Z47+Z48+Z49+Z50+Z51)/5 -> 0 | S47: =AD47/AC47 -> #DIV/0! | T47: =(AC47+AC48+AC49+AC50+AC51)/5 -> 0 | V47: =AG47/AF47 -> #DIV/0! | W47: =(AF47+AF48+AF49+AF50+AF51)/5 -> 0
...

Sheet Weather
B3: Normative Weather | P3: I propose to delete this page in general, because:
P4: 1. We have normative values in one single standard, for different climatic zones and different heating durations (3 zones x 2 types of heating duration = 6 tables)
B5: Month | C5: 1 | D5: 2 | E5: 3 | F5: 4 | G5: 5 | H5: 6 | I5: 7 | J5: 8 | K5: 9 | L5: 10 | M5: 11 | N5: 12 | P5: 2. We never use actual weather in calculations, only the normative because we don't have an open acces to weather data, it costs a lot of money and unfortunately even the Ministry cannot afford to by it yet to update the 40yo database from standards
B6: Ambient temp | C6: -1.7 | D6: -0.7 | E6: 4.5 | F6: 11 | G6: 17 | H6: 19.7 | I6: 21.1 | J6: 21 | K6: 15.3 | L6: 10.6 | M6: 5.4 | N6: -0.8 | P6: 3. These tables shouldn't be here because this data is fixed by the standard and is not an input data.
B7: North | C7: 9 | D7: 14 | E7: 25 | F7: 33 | G7: 46 | H7: 53 | I7: 53 | J7: 37 | K7: 27 | L7: 19 | M7: 12 | N7: 9
B8: East | C8: 17 | D8: 32 | E8: 63 | F8: 87 | G8: 111 | H8: 105 | I8: 117 | J8: 100 | K8: 76 | L8: 53 | M8: 28 | N8: 16
B9: South | C9: 47 | D9: 72 | E9: 112 | F9: 109 | G9: 104 | H9: 90 | I9: 100 | J9: 111 | K9: 119 | L9: 115 | M9: 75 | N9: 49
B10: West | C10: 19 | D10: 32 | E10: 66 | F10: 87 | G10: 106 | H10: 103 | I10: 108 | J10: 97 | K10: 79 | L10: 59 | M10: 30 | N10: 19
B11: Global | C11: 27 | D11: 49 | E11: 100 | F11: 140 | G11: 180 | H11: 177 | I11: 187 | J11: 164 | K11: 122 | L11: 81 | M11: 41 | N11: 26
B12: Dew point | C12: -3.6 | D12: -3.4 | E12: -0.3 | F12: 4.7 | G12: 10.4 | H12: 13.3 | I12: 15.5 | J12: 14.9 | K12: 10.7 | L12: 6.9 | M12: 2.5 | N12: -2.7
B13: Sky temp | C13: -11.7 | D13: -12.4 | E13: -8.4 | F13: -2.4 | G13: 4.5 | H13: 7.4 | I13: 9.6 | J13: 9.7 | K13: 4.6 | L13: -0.2 | M13: -4.9 | N13: -11.4
B14: Ground temp | C14: -1.7 | D14: -0.7 | E14: 4.5 | F14: 11 | G14: 17 | H14: 19.7 | I14: 21.1 | J14: 21 | K14: 15.3 | L14: 10.6 | M14: 5.4 | N14: -0.8
B16: Actual weather data of | E16: year
B18: Month | C18: 1 | D18: 2 | E18: 3 | F18: 4 | G18: 5 | H18: 6 | I18: 7 | J18: 8 | K18: 9 | L18: 10 | M18: 11 | N18: 12
B19: Ambient temp | C19: -1.7 | D19: -0.7 | E19: 4.5 | F19: 11 | G19: 17 | H19: 19.7 | I19: 21.1 | J19: 21 | K19: 15.3 | L19: 10.6 | M19: 5.4 | N19: -0.8
B20: North | C20: 9 | D20: 14 | E20: 25 | F20: 33 | G20: 46 | H20: 53 | I20: 53 | J20: 37 | K20: 27 | L20: 19 | M20: 12 | N20: 9
B21: East | C21: 17 | D21: 32 | E21: 63 | F21: 87 | G21: 111 | H21: 105 | I21: 117 | J21: 100 | K21: 76 | L21: 53 | M21: 28 | N21: 16
B22: South | C22: 47 | D22: 72 | E22: 112 | F22: 109 | G22: 104 | H22: 90 | I22: 100 | J22: 111 | K22: 119 | L22: 115 | M22: 75 | N22: 49
B23: West | C23: 19 | D23: 32 | E23: 66 | F23: 87 | G23: 106 | H23: 103 | I23: 108 | J23: 97 | K23: 79 | L23: 59 | M23: 30 | N23: 19
B24: Global | C24: 27 | D24: 49 | E24: 100 | F24: 140 | G24: 180 | H24: 177 | I24: 187 | J24: 164 | K24: 122 | L24: 81 | M24: 41 | N24: 26
B25: Dew point | C25: -3.6 | D25: -3.4 | E25: -0.3 | F25: 4.7 | G25: 10.4 | H25: 13.3 | I25: 15.5 | J25: 14.9 | K25: 10.7 | L25: 6.9 | M25: 2.5 | N25: -2.7
B26: Sky temp | C26: -11.7 | D26: -12.4 | E26: -8.4 | F26: -2.4 | G26: 4.5 | H26: 7.4 | I26: 9.6 | J26: 9.7 | K26: 4.6 | L26: -0.2 | M26: -4.9 | N26: -11.4
B27: Ground temp | C27: -1.7 | D27: -0.7 | E27: 4.5 | F27: 11 | G27: 17 | H27: 19.7 | I27: 21.1 | J27: 21 | K27: 15.3 | L27: 10.6 | M27: 5.4 | N27: -0.8
B29: Actual weather data of | E29: year
B31: Month | C31: 1 | D31: 2 | E31: 3 | F31: 4 | G31: 5 | H31: 6 | I31: 7 | J31: 8 | K31: 9 | L31: 10 | M31: 11 | N31: 12
B32: Ambient temp | C32: -1.7 | D32: -0.7 | E32: 4.5 | F32: 11 | G32: 17 | H32: 19.7 | I32: 21.1 | J32: 21 | K32: 15.3 | L32: 10.6 | M32: 5.4 | N32: -0.8
B33: North | C33: 9 | D33: 14 | E33: 25 | F33: 33 | G33: 46 | H33: 53 | I33: 53 | J33: 37 | K33: 27 | L33: 19 | M33: 12 | N33: 9
B34: East | C34: 17 | D34: 32 | E34: 63 | F34: 87 | G34: 111 | H34: 105 | I34: 117 | J34: 100 | K34: 76 | L34: 53 | M34: 28 | N34: 16
B35: South | C35: 47 | D35: 72 | E35: 112 | F35: 109 | G35: 104 | H35: 90 | I35: 100 | J35: 111 | K35: 119 | L35: 115 | M35: 75 | N35: 49
B36: West | C36: 19 | D36: 32 | E36: 66 | F36: 87 | G36: 106 | H36: 103 | I36: 108 | J36: 97 | K36: 79 | L36: 59 | M36: 30 | N36: 19
B37: Global | C37: 27 | D37: 49 | E37: 100 | F37: 140 | G37: 180 | H37: 177 | I37: 187 | J37: 164 | K37: 122 | L37: 81 | M37: 41 | N37: 26
B38: Dew point | C38: -3.6 | D38: -3.4 | E38: -0.3 | F38: 4.7 | G38: 10.4 | H38: 13.3 | I38: 15.5 | J38: 14.9 | K38: 10.7 | L38: 6.9 | M38: 2.5 | N38: -2.7
B39: Sky temp | C39: -11.7 | D39: -12.4 | E39: -8.4 | F39: -2.4 | G39: 4.5 | H39: 7.4 | I39: 9.6 | J39: 9.7 | K39: 4.6 | L39: -0.2 | M39: -4.9 | N39: -11.4
B40: Ground temp | C40: -1.7 | D40: -0.7 | E40: 4.5 | F40: 11 | G40: 17 | H40: 19.7 | I40: 21.1 | J40: 21 | K40: 15.3 | L40: 10.6 | M40: 5.4 | N40: -0.8
B42: Actual weather data of | E42: year
B44: Month | C44: 1 | D44: 2 | E44: 3 | F44: 4 | G44: 5 | H44: 6 | I44: 7 | J44: 8 | K44: 9 | L44: 10 | M44: 11 | N44: 12
B45: Ambient temp | C45: -1.7 | D45: -0.7 | E45: 4.5 | F45: 11 | G45: 17 | H45: 19.7 | I45: 21.1 | J45: 21 | K45: 15.3 | L45: 10.6 | M45: 5.4 | N45: -0.8
B46: North | C46: 9 | D46: 14 | E46: 25 | F46: 33 | G46: 46 | H46: 53 | I46: 53 | J46: 37 | K46: 27 | L46: 19 | M46: 12 | N46: 9
B47: East | C47: 17 | D47: 32 | E47: 63 | F47: 87 | G47: 111 | H47: 105 | I47: 117 | J47: 100 | K47: 76 | L47: 53 | M47: 28 | N47: 16
B48: South | C48: 47 | D48: 72 | E48: 112 | F48: 109 | G48: 104 | H48: 90 | I48: 100 | J48: 111 | K48: 119 | L48: 115 | M48: 75 | N48: 49
...

Sheet U-values
C2: Calculation of Uvalue for external wall before renovation (W1) | J2: Calculation of Uvalue for external wall after renovation (W1)
C3: Layers | E3: Thickness | F3: Thermal conductivity | H3: Thermal resistance | J3: Layers | L3: Thickness | M3: Thermal conductivity | O3: Thermal resistance | Q3: Rezistența termică a suprafeței din Interior / Exterior [m²K/W] - SM SR EN ISO 6946
Q4: Rezistența termică a suprafeței în m2K/W | T4: Rint | U4: Rext
E5: [m] | F5: [W/mK] | H5: [m²K/W] | L5: [m] | M5: [W/mK] | O5: [m²K/W]
C6: 1 | D6: Internal plaster | E6: 0.002 | F6: =IFERROR(VLOOKUP(D6,$Y$7:$Z$46,2,FALSE),"") -> 0.7 | H6: =IFERROR(IF(F6=0,0,E6/F6),"") -> 0.0028571429 | J6: 1 | K6: Internal plaster | L6: 0.002 | M6: =IFERROR(VLOOKUP(K6,$Y$7:$Z$46,2,FALSE),"") -> 0.7 | O6: =IFERROR(IF(M6=0,0,L6/M6),"") -> 0.0028571429 | Q6: Tashqi muhit bilan aloqada bo'lgan vertikal element (masalan, devor) | T6: 0.115 | U6: 0.04 | Y6: Material de construcție | Z6: λ,W/(m∙K) | AA6: Column1
C7: 2 | D7: Concrete/sand mix | E7: 0.01 | F7: =IFERROR(VLOOKUP(D7,$Y$7:$Z$46,2,FALSE),"") -> 0.76 | H7: =IFERROR(IF(F7=0,0,E7/F7),"") -> 0.013157895 | J7: 2 | K7: Concrete/sand mix | L7: 0.01 | M7: =IFERROR(VLOOKUP(K7,$Y$7:$Z$46,2,FALSE),"") -> 0.76 | O7: =IFERROR(IF(M7=0,0,L7/M7),"") -> 0.013157895 | Q7: Isitilgan makon bilan aloqada bo'lgan devor | T7: 0.115 | U7: 0.115 | Y7: Internal plaster | Z7: 0.7
C8: 3 | D8: Bricks | E8: 0.38 | F8: =IFERROR(VLOOKUP(D8,$Y$7:$Z$46,2,FALSE),"") -> 0.7 | H8: =IFERROR(IF(F8=0,0,E8/F8),"") -> 0.54285714 | J8: 3 | K8: Bricks | L8: 0.38 | M8: =IFERROR(VLOOKUP(K8,$Y$7:$Z$46,2,FALSE),"") -> 0.7 | O8: =IFERROR(IF(M8=0,0,L8/M8),"") -> 0.54285714 | Q8: Yer bilan aloqada bo'lgan devor (vertikal) | T8: 2.1 | U8: 0 | Y8: External plaster | Z8: 0.76
C9: 4 | D9: Concrete/sand mix | E9: 0.01 | F9: =IFERROR(VLOOKUP(D9,$Y$7:$Z$46,2,FALSE),"") -> 0.76 | H9: =IFERROR(IF(F9=0,0,E9/F9),"") -> 0.013157895 | J9: 4 | K9: Concrete/sand mix | L9: 0.01 | M9: =IFERROR(VLOOKUP(K9,$Y$7:$Z$46,2,FALSE),"") -> 0.76 | O9: =IFERROR(IF(M9=0,0,L9/M9),"") -> 0.013157895 | Q9: Tom tashqi muhit bilan aloqada | T9: 0.115 | U9: 0.04 | Y9: Concrete | Z9: 1.92
C10: 5 | F10: =IFERROR(VLOOKUP(D10,$Y$7:$Z$33,2,FALSE),"") | H10: =IFERROR(IF(F10=0,0,E10/F10),"") | J10: 5 | M10: =IFERROR(VLOOKUP(K10,$Y$7:$Z$46,2,FALSE),"") | O10: =IFERROR(IF(M10=0,0,L10/M10),"") | Q10: Isitilmagan makon ostidagi shift | T10: 0.115 | U10: 0.083 | Y10: Concrete mixed with EPS (G-Sort) | Z10: 0.07
C11: 6 | F11: =IFERROR(VLOOKUP(D11,$Y$7:$Z$46,2,FALSE),"") | H11: =IFERROR(IF(F11=0,0,E11/F11),"") | J11: 6 | K11: Mineral wool MW | L11: 0.1 | M11: =IFERROR(VLOOKUP(K11,$Y$7:$Z$46,2,FALSE),"") -> 0.038 | O11: =IFERROR(IF(M11=0,0,L11/M11),"") -> 2.6315789 | Q11: Ochiq maydon ustidagi pol | T11: 0.115 | U11: 0.04 | Y11: Concrete with stones | Z11: 1.74
J12: 7 | K12: Ruberoid | L12: 0.005 | M12: =IFERROR(VLOOKUP(K12,$Y$7:$Z$46,2,FALSE),"") -> 0.17 | O12: =IFERROR(IF(M12=0,0,L12/M12),"") -> 0.029411765 | Y12: Polistirolbeton | Z12: 0.055
J13: 8 | K13: External plaster | L13: 0.005 | M13: =IFERROR(VLOOKUP(K13,$Y$7:$Z$46,2,FALSE),"") -> 0.76 | O13: =IFERROR(IF(M13=0,0,L13/M13),"") -> 0.0065789474
C14: Total | E14: =SUM(E6:E11) -> 0.402 | H14: =SUM(H6:H11) -> 0.57203008 | J14: Total | L14: =SUM(L6:L13) -> 0.512 | O14: =SUM(O6:O13) -> 3.2395997 | Q14: Isitilgan maydon ustidagi pol | T14: 0.115 | U14: 0.166 | Y14: Concrete with expanded clay | Z14: 0.52
C15: Thermal resistance of interior surface | F15: Rint | G15: [m²K/W] | H15: =T6 -> 0.115 | J15: Thermal resistance of interior surface | M15: Rint | N15: [m²K/W] | O15: =T6 -> 0.115 | Q15: Yer bilan aloqada pol | T15: 2.1 | U15: 0 | Y15: Aerated concrete (YTONG) | Z15: 0.41
C16: Thermal resistance of exterior surface | F16: Rext | G16: [m²K/W] | H16: =U6 -> 0.04 | J16: Thermal resistance of exterior surface | M16: Rext | N16: [m²K/W] | O16: =U6 -> 0.04 | Y16: Aggregated slug (from boilers) | Z16: 0.76
C17: Heat transfer coefficient (U value) | G17: [W/m²K] | H17: =1/(H16+H15+H14) -> 1.3754589 | J17: Heat transfer coefficient (U value) | N17: [W/m²K] | O17: =1/(O16+O15+O14) -> 0.29458554 | Y17: Ruberoid | Z17: 0.17
Y18: Bitumen polimeric materials | Z18: 0.27
Y19: Wood (pine) | Z19: 0.29
Y20: Mosaic | Z20: 1.74
Y21: Marble | Z21: 2.91
Y22: Granit | Z22: 3.49
Y23: Concrete/sand mix | Z23: 0.76
Y24: Limestone | Z24: 0.73
Y25: Bricks | Z25: 0.7
Y26: Hollow bricks | Z26: 0.58
Y27: Linoleum | Z27: 0.35
Y28: Expanded clay | Z28: 0.17
Y29: Tile | Z29: 1.1
Y30: Clay layer with straw | Z30: 0.65
R31: roof | Y31: Expanded polysterene EPS | Z31: 0.038
Y32: Extruded polysterene XPS | Z32: 0.035
C33: Calculation of Uvalue for external socle before renovation (Socle1)(heated space) | J33: Calculation of Uvalue for external socle after renovation (Socle1)(heated space) | R33: floor | Y33: Mineral wool MW | Z33: 0.038
C34: Layers | E34: Thickness | F34: Thermal conductivity | H34: Thermal resistance | J34: Layers | L34: Thickness | M34: Thermal conductivity | O34: Thermal resistance | Y34: Magnesium oxide plate | Z34: 0.21
Y35: Concrete hollow panels | Z35: 1.295 | AA35: Bo'shliqli beton panel 220mm
E36: [m] | F36: [W/mK] | H36: [m²K/W] | L36: [m] | M36: [W/mK] | O36: [m²K/W] | Y36: Decorative stone | Z36: 2.1
C37: 1 | D37: Concrete with stones | E37: 0.6 | F37: =IFERROR(VLOOKUP(D37,$Y$7:$Z$46,2,FALSE),"") -> 1.74 | H37: =IFERROR(IF(F37=0,0,E37/F37),"") -> 0.34482759 | J37: 1 | K37: Concrete with stones | L37: 0.6 | M37: =IFERROR(VLOOKUP(K37,$Y$7:$Z$46,2,FALSE),"") -> 1.74 | O37: =IFERROR(IF(M37=0,0,L37/M37),"") -> 0.34482759 | Y37: Sintipon prokladka | Z37: 0.04
C38: 2 | D38: Concrete/sand mix | E38: 0.02 | F38: =IFERROR(VLOOKUP(D38,$Y$7:$Z$46,2,FALSE),"") -> 0.76 | H38: =IFERROR(IF(F38=0,0,E38/F38),"") -> 0.026315789 | J38: 2 | K38: Concrete/sand mix | L38: 0.02 | M38: =IFERROR(VLOOKUP(K38,$Y$7:$Z$46,2,FALSE),"") -> 0.76 | O38: =IFERROR(IF(M38=0,0,L38/M38),"") -> 0.026315789 | Y38: Gidro-bugʻ izolyatsiyasi (Ustki) | Z38: 0.4
C39: 3 | D39: Decorative stone | E39: 0.03 | F39: =IFERROR(VLOOKUP(D39,$Y$7:$Z$46,2,FALSE),"") -> 2.1 | H39: =IFERROR(IF(F39=0,0,E39/F39),"") -> 0.014285714 | J39: 3 | K39: Decorative stone | L39: 0.03 | M39: =IFERROR(VLOOKUP(K39,$Y$7:$Z$46,2,FALSE),"") -> 2.1 | O39: =IFERROR(IF(M39=0,0,L39/M39),"") -> 0.014285714 | Y39: Tunika shifer | Z39: 0.01
C40: 4 | F40: =IFERROR(VLOOKUP(D40,$Y$7:$Z$46,2,FALSE),"") | H40: =IFERROR(IF(F40=0,0,E40/F40),"") | J40: 4 | K40: Mineral wool MW | L40: 0.1 | M40: =IFERROR(VLOOKUP(K40,$Y$7:$Z$46,2,FALSE),"") -> 0.038 | O40: =IFERROR(IF(M40=0,0,L40/M40),"") -> 2.6315789 | Y40: Pol taxta | Z40: 0.29
C41: 5 | F41: =IFERROR(VLOOKUP(D41,$Y$7:$Z$33,2,FALSE),"") | H41: =IFERROR(IF(F41=0,0,E41/F41),"") | J41: 5 | K41: Clay layer with straw | L41: 0.004 | M41: =IFERROR(VLOOKUP(K41,$Y$7:$Z$33,2,FALSE),"") -> 0.65 | O41: =IFERROR(IF(M41=0,0,L41/M41),"") -> 0.0061538462 | Y41: Gips (Гипс) | Z41: 0.35
...

Sheet Losses env. before
B2: Cumulative annual heat losses before renovation through building envelope
B4: Element | C4: In contact with | D4: Wall type | E4: Area | F4: U value | G4: Qtot
E5: [m²] | F5: [W/m²K] | G5: [kWh/y]
B6: Walls | C6: Environment | G6: =IF(D6=D42,SUM(E42:K42),0) -> 0
D7: =Envelope!AG104 -> W1 | E7: =Envelope!AH104 -> 1492.9 | F7: ='U-values'!H17 -> 1.3754589 | G7: =IF(D7=D43,SUM(E43:K44),0) -> 95776.559
D9: =Envelope!AG106 -> Socle 1. (heated space) | E9: =Envelope!AH106 -> 0 | F9: ='U-values'!H46 -> 1.8503815 | G9: =IF(D9=D45,SUM(E45:K45),0) -> 0
C11: Ground | D11: =Envelope!AG108 -> Socle 2 | E11: =Envelope!AH108 -> 0 | F11: ='U-values'!H76 -> 0.40593181 | G11: =IF(D11=D47,SUM(E47:K47),0) -> 0
C13: Total annual heat losses through walls | G13: =SUM(G6:G12) -> 95776.559
B14: Roof | C14: Environment | D14: =Envelope!AG123 -> R2 | E14: =Envelope!AH123 -> 0 | F14: ='U-values'!H107 -> #DIV/0!
C16: Semi-closed un-heated space
C18: Closed un-heated space | D18: =Envelope!AG122 -> R1 | E18: =Envelope!AH122 -> 1279.175 | F18: ='U-values'!H91 -> 2.061871 | G18: =IF(D18=D54,SUM(E53:K54),0) -> 123019.04
C19: Total annual heat losses through roof | G19: =SUM(G14:G18) -> 123019.04
B20: Floor | C20: Ground | G20: =IF(D20=D56,SUM(E56:K56),0) -> 0
C21: Closed un-heated basement | D21: =Envelope!AG115 -> F1 | E21: =Envelope!AH115 -> 1279.175 | F21: ='U-values'!H122 -> 0.42814201 | G21: =IF(D21=D57,SUM(E57:K57),0) -> 14809.505
C22: In contact with environment | D22: =Envelope!AG116 -> F2 | E22: =Envelope!AH116 -> 0
C23: Total annual heat losses through floor | G23: =SUM(G20:G22) -> 14809.505
B24: Windows and Doors | D24: =Envelope!AG86 -> Win1 | E24: =Envelope!AI86 -> 0 | F24: =Envelope!AH86 -> 2.56 | G24: =IF(D24=D60,SUM(E60:K60),0) -> 0
D25: =Envelope!AG87 -> Win2 | E25: =Envelope!AI87 -> 0 | F25: =Envelope!AH87 -> 2.78 | G25: =IF(D25=D61,SUM(E61:K61),0) -> 0
D26: =Envelope!AG88 -> Win3 | E26: =Envelope!AI88 -> 256.62 | F26: =Envelope!AH88 -> 2.94 | G26: =IF(D26=D62,SUM(E62:K62),0) -> 20401.429
G27: =IF(D27=D63,SUM(E63:K63),0) -> 0
D28: =Envelope!AG90 -> D1 | E28: =Envelope!AI90 -> 61.43 | F28: =Envelope!AH90 -> 3.5 | G28: =IF(D28=D64,SUM(E64:K64),0) -> 5813.9502
D29: =Envelope!AG91 -> D2 | E29: =Envelope!AI91 -> 0 | F29: =Envelope!AH91 -> 4 | G29: =IF(D29=D65,SUM(E65:K65),0) -> 0
D30: =Envelope!AG92 -> D3 | E30: =Envelope!AI92 -> 0 | F30: =Envelope!AH92 -> 5.88 | G30: =IF(D30=D66,SUM(E66:K66),0) -> 0
C31: Total annual heat losses through windows and doors | G31: =SUM(G24:G30) -> 26215.379
B32: Total annual heat losses through building envelope | G32: =G31+G23+G19+G13 -> 259820.49
B34: Monthly heat losses before renovation through building envelope | M34: Heating season monthly data for Hospitals placed in II Climatic zone
N35: 13.8 | O35: 8.5 | P35: 3.5 | Q35: 1.9 | R35: 3.9 | S35: 9.4 | T35: 15.5
M36: Month | N36: Oct | O36: Nov | P36: Dec | Q36: Jan | R36: Feb | S36: Mar | T36: Apr
M37: Average temp [°C] | N37: 12,4 | O37: 6,6 | P37: 1,2 | Q37: -0,1 | R37: 2,5 | S37: 8,6 | T37: 15,3
M38: Duration [days] | N38: 15 | O38: 27 | P38: 28 | Q38: 28 | R38: 25 | S38: 28 | T38: 12
E39: N | F39: O | G39: P | H39: Q Jan | I39: R | J39: S | K39: T | M39: Δt [°C] | N39: =Building_data!$D$9-'Losses env. before'!N37 -> 9.6 | O39: =Building_data!$D$9-'Losses env. before'!O37 -> 15.4 | P39: =Building_data!$D$9-'Losses env. before'!P37 -> 20.8 | Q39: =Building_data!$D$9-'Losses env. before'!Q37 -> 22.1 | R39: =Building_data!$D$9-'Losses env. before'!R37 -> 19.5 | S39: =Building_data!$D$9-'Losses env. before'!S37 -> 13.4 | T39: =Building_data!$D$9-'Losses env. before'!T37 -> 6.7
B40: Element | C40: In contact with | D40: Wall type | E40: Q Oct | F40: Q Nov | G40: Q Dec | H40: Q Jan | I40: Q Feb | J40: Q Mar | K40: Q Apr | M40: Duration [h] | N40: =N38*Building_data!$D$14 -> 150 | O40: =O38*Building_data!$D$14 -> 270 | P40: =P38*Building_data!$D$14 -> 280 | Q40: =Q38*Building_data!$D$14 -> 280 | R40: =R38*Building_data!$D$14 -> 250 | S40: =S38*Building_data!$D$14 -> 280 | T40: =T38*Building_data!$D$14 -> 120
E41: [kWh/month] | F41: [kWh/month] | G41: [kWh/month] | H41: [kWh/month] | I41: [kWh/month] | J41: [kWh/month] | K41: [kWh/month]
B42: Walls | C42: Environment | D42: =D6 -> 0 | E42: =($E$6*$F$6*N39*N40)/1000 -> 0 | F42: =($E$6*$F$6*O39*O40)/1000 -> 0 | G42: =($E$6*$F$6*P39*P40)/1000 -> 0 | H42: =($E$6*$F$6*Q39*Q40)/1000 -> 0 | I42: =($E$6*$F$6*R39*R40)/1000 -> 0 | J42: =($E$6*$F$6*S39*S40)/1000 -> 0 | K42: =($E$6*$F$6*T39*T40)/1000 -> 0 | M42: Month | N42: Oct | O42: Nov | P42: Dec | Q42: Jan | R42: Feb | S42: Mar | T42: Apr
D43: =D7 -> W1 | E43: =($E$7*$F$7*N39*N40)/1000 -> 2956.9286 | F43: =($E$7*$F$7*O39*O40)/1000 -> 8538.1312 | G43: =($E$7*$F$7*P39*P40)/1000 -> 11959.133 | H43: =($E$7*$F$7*Q39*Q40)/1000 -> 12706.579 | I43: =($E$7*$F$7*R39*R40)/1000 -> 10010.435 | J43: =($E$7*$F$7*S39*S40)/1000 -> 7704.4417 | K43: =($E$7*$F$7*T39*T40)/1000 -> 1650.9518 | M43: Average temp [°C] | N43: 12,4 | O43: 6,6 | P43: 1,2 | Q43: -0,1 | R43: 2,5 | S43: 8,6 | T43: 15,3
D44: W1 | E44: =($E$7*$F$7*N45*N46)/1000 -> 689.95 | F44: =($E$7*$F$7*O45*O46)/1000 -> 5743.8337 | G44: =($E$7*$F$7*P45*P46)/1000 -> 10303.253 | H44: =($E$7*$F$7*Q45*Q46)/1000 -> 11349.677 | I44: =($E$7*$F$7*R45*R46)/1000 -> 8265.026 | J44: =($E$7*$F$7*S45*S46)/1000 -> 4346.685 | K44: =($E$7*$F$7*T45*T46)/1000 -> -448.4675 | M44: Duration [days] | N44: 15 | O44: 27 | P44: 28 | Q44: 28 | R44: 25 | S44: 28 | T44: 12
D45: =D9 -> Socle 1. (heated space) | E45: =($E$9*$F$9*N39*N40)/1000 -> 0 | F45: =($E$9*$F$9*O39*O40)/1000 -> 0 | G45: =($E$9*$F$9*P39*P40)/1000 -> 0 | H45: =($E$9*$F$9*Q39*Q40)/1000 -> 0 | I45: =($E$9*$F$9*R39*R40)/1000 -> 0 | J45: =($E$9*$F$9*S39*S40)/1000 -> 0 | K45: =($E$9*$F$9*T39*T40)/1000 -> 0 | M45: Δt [°C] | N45: =Building_data!$D8-'Losses env. before'!N43 -> 1.6 | O45: =Building_data!$D8-'Losses env. before'!O43 -> 7.4 | P45: =Building_data!$D8-'Losses env. before'!P43 -> 12.8 | Q45: =Building_data!$D8-'Losses env. before'!Q43 -> 14.1 | R45: =Building_data!$D8-'Losses env. before'!R43 -> 11.5 | S45: =Building_data!$D8-'Losses env. before'!S43 -> 5.4 | T45: =Building_data!$D8-'Losses env. before'!T43 -> -1.3
D46: =D10 -> 0 | E46: =($E$10*$F$10*N39*N40)/1000 -> 0 | F46: =($E$10*$F$10*O39*O40)/1000 -> 0 | G46: =($E$10*$F$10*P39*P40)/1000 -> 0 | H46: =($E$10*$F$10*Q39*Q40)/1000 -> 0 | I46: =($E$10*$F$10*R39*R40)/1000 -> 0 | J46: =($E$10*$F$10*S39*S40)/1000 -> 0 | K46: =($E$10*$F$10*T39*T40)/1000 -> 0 | M46: Duration [h] | N46: =N44*Building_data!$D$13 -> 210 | O46: =O44*Building_data!$D$13 -> 378 | P46: =P44*Building_data!$D$13 -> 392 | Q46: =Q44*Building_data!$D$13 -> 392 | R46: =R44*Building_data!$D$13 -> 350 | S46: =S44*Building_data!$D$13 -> 392 | T46: =T44*Building_data!$D$13 -> 168
C47: Ground | D47: =D11 -> Socle 2 | E47: =($E$11*$F$11*N39*N40)/1000 -> 0 | F47: =($E$11*$F$11*O39*O40)/1000 -> 0 | G47: =($E$11*$F$11*P39*P40)/1000 -> 0 | H47: =($E$11*$F$11*Q39*Q40)/1000 -> 0 | I47: =($E$11*$F$11*R39*R40)/1000 -> 0 | J47: =($E$11*$F$11*S39*S40)/1000 -> 0 | K47: =($E$11*$F$11*T39*T40)/1000 -> 0
C48: Closed un-heated space | D48: =D12 -> 0 | E48: =($E$12*$F$12*N39*N40)/1000 -> 0 | F48: =($E$12*$F$12*O39*O40)/1000 -> 0 | G48: =($E$12*$F$12*P39*P40)/1000 -> 0 | H48: =($E$12*$F$12*Q39*Q40)/1000 -> 0 | I48: =($E$12*$F$12*R39*R40)/1000 -> 0 | J48: =($E$12*$F$12*S39*S40)/1000 -> 0 | K48: =($E$12*$F$12*T39*T40)/1000 -> 0
...

Sheet Losses env. after
B2: Cumulative annual heat losses after renovation through building envelope
B4: Element | C4: In contact with | D4: Wall type | E4: Area | F4: U value | G4: Qtot
E5: [m²] | F5: [W/m²K] | G5: [kWh/y]
B6: Walls | C6: Environment | G6: =IF(D6=D38,SUM(E38:K38),0) -> 0
D7: ='Losses env. before'!D7 -> W1 | E7: ='Losses env. before'!E7 -> 1492.9 | F7: ='U-values'!O17 -> 0.29458554 | G7: =IF(D7=D39,SUM(E39:K40),0) -> 20512.71
D9: ='Losses env. before'!D9 -> Socle 1. (heated space) | E9: ='Losses env. before'!E9 -> 0 | F9: ='U-values'!O46 -> 0.31425697 | G9: =IF(D9=D41,SUM(E41:K41),0) -> 0
C11: Ground | D11: ='Losses env. before'!D11 -> Socle 2 | E11: ='Losses env. before'!E11 -> 0 | F11: ='U-values'!O76 -> 0.1958807 | G11: =IF(D11=D43,SUM(E43:K43),0) -> 0
C12: Closed un-heated space | G12: =IF(D12=D44,SUM(E44:K44),0) -> 0
C13: Total annual heat losses through walls | G13: =SUM(G6:G12) -> 20512.71
B14: Roof | C14: Environment | D14: R2 | E14: ='Losses env. before'!E14 -> 0
G15: =IF(D15=D47,SUM(E47:K47),0) -> 0
C16: Semi-closed un-heated space | G16: =IF(D16=D48,SUM(E48:K48),0) -> 0
C18: Closed un-heated space | D18: R1 | E18: ='Losses env. before'!E18 -> 1279.175 | F18: ='U-values'!O91 -> 0.31130642 | G18: =IF(D18=D50,SUM(E49:K50),0) -> 18573.721
C19: Total annual heat losses through roof | G19: =SUM(G14:G18) -> 18573.721
B20: Floor | C20: Ground | G20: =IF(D20=D52,SUM(E52:K52),0) -> 0
C21: Closed un-heated basement | D21: F1 | E21: ='Losses env. before'!E21 -> 1279.175 | F21: ='U-values'!O122 -> 0.42814201 | G21: =IF(D21=D53,SUM(E53:K53),0) -> 14809.505
C22: In contact with environment | D22: F2 | E22: ='Losses env. before'!E22 -> 0
C23: Total annual heat losses through floor | G23: =SUM(G20:G22) -> 14809.505
B24: Windows and Doors | D24: Win4 | E24: ='Losses env. before'!E24+'Losses env. before'!E25+'Losses env. before'!E26 -> 256.62 | F24: 1.5 | G24: =IF(D24=D56,SUM(E56:K56),0) -> 10408.892
G25: =IF(D25=D57,SUM(E57:K57),0) -> 0
D26: D4 | E26: ='Losses env. before'!E28+'Losses env. before'!E29+'Losses env. before'!E30 -> 61.43 | F26: 1.8 | G26: =IF(D26=D58,SUM(E58:K58),0) -> 2990.0315
C27: Total annual heat losses through windows and doors | G27: =SUM(G24:G26) -> 13398.924
B28: Total annual heat losses through building envelope | G28: =G27+G23+G19+G13 -> 67294.86
B30: Monthly heat losses before renovation through building envelope | M30: Heating season monthly data for Hospitals placed in II Climatic zone
M32: Month | N32: Oct | O32: Nov | P32: Dec | Q32: Jan | R32: Feb | S32: Mar | T32: Apr
M33: Average temp [°C] | N33: ='Losses env. before'!N37 -> 12,4 | O33: ='Losses env. before'!O37 -> 6,6 | P33: ='Losses env. before'!P37 -> 1,2 | Q33: ='Losses env. before'!Q37 -> -0,1 | R33: ='Losses env. before'!R37 -> 2,5 | S33: ='Losses env. before'!S37 -> 8,6 | T33: ='Losses env. before'!T37 -> 15,3
M34: Duration [days] | N34: 15 | O34: 27 | P34: 28 | Q34: 28 | R34: 25 | S34: 28 | T34: 12
E35: N | F35: O | G35: P | H35: Q Jan | I35: R | J35: S | K35: T | M35: Δt [°C] | N35: =Building_data!$D$9-'Losses env. before'!N37 -> 9.6 | O35: =Building_data!$D$9-'Losses env. before'!O37 -> 15.4 | P35: =Building_data!$D$9-'Losses env. before'!P37 -> 20.8 | Q35: =Building_data!$D$9-'Losses env. before'!Q37 -> 22.1 | R35: =Building_data!$D$9-'Losses env. before'!R37 -> 19.5 | S35: =Building_data!$D$9-'Losses env. before'!S37 -> 13.4 | T35: =Building_data!$D$9-'Losses env. before'!T37 -> 6.7
B36: Element | C36: In contact with | D36: Wall type | E36: Q Oct | F36: Q Nov | G36: Q Dec | H36: Q Jan | I36: Q Feb | J36: Q Mar | K36: Q Apr | M36: Duration [h] | N36: =N34*Building_data!$D$14 -> 150 | O36: =O34*Building_data!$D$14 -> 270 | P36: =P34*Building_data!$D$14 -> 280 | Q36: =Q34*Building_data!$D$14 -> 280 | R36: =R34*Building_data!$D$14 -> 250 | S36: =S34*Building_data!$D$14 -> 280 | T36: =T34*Building_data!$D$14 -> 120
E37: [kWh/month] | F37: [kWh/month] | G37: [kWh/month] | H37: [kWh/month] | I37: [kWh/month] | J37: [kWh/month] | K37: [kWh/month]
B38: Walls | C38: Environment | D38: =D6 -> 0 | E38: =($E$6*$F$6*N35*N36)/1000 -> 0 | F38: =($E$6*$F$6*O35*O36)/1000 -> 0 | G38: =($E$6*$F$6*P35*P36)/1000 -> 0 | H38: =($E$6*$F$6*Q35*Q36)/1000 -> 0 | I38: =($E$6*$F$6*R35*R36)/1000 -> 0 | J38: =($E$6*$F$6*S35*S36)/1000 -> 0 | K38: =($E$6*$F$6*T35*T36)/1000 -> 0 | M38: Month | N38: Oct | O38: Nov | P38: Dec | Q38: Jan | R38: Feb | S38: Mar | T38: Apr
D39: =D7 -> W1 | E39: =($E$7*$F$7*N35*N36)/1000 -> 633.29293 | F39: =($E$7*$F$7*O35*O36)/1000 -> 1828.6333 | G39: =($E$7*$F$7*P35*P36)/1000 -> 2561.3181 | H39: =($E$7*$F$7*Q35*Q36)/1000 -> 2721.4004 | I39: =($E$7*$F$7*R35*R36)/1000 -> 2143.9604 | J39: =($E$7*$F$7*S35*S36)/1000 -> 1650.0799 | K39: =($E$7*$F$7*T35*T36)/1000 -> 353.58855 | M39: Average temp [°C] | N39: ='Losses env. before'!N43 -> 12,4 | O39: ='Losses env. before'!O43 -> 6,6 | P39: ='Losses env. before'!P43 -> 1,2 | Q39: ='Losses env. before'!Q43 -> -0,1 | R39: ='Losses env. before'!R43 -> 2,5 | S39: ='Losses env. before'!S43 -> 8,6 | T39: ='Losses env. before'!T43 -> 15,3
D40: =D8 -> 0 | E40: =($E$7*$F$7*N41*N42)/1000 -> 147.76835 | F40: =($E$7*$F$7*O41*O42)/1000 -> 1230.1715 | G40: =($E$7*$F$7*P41*P42)/1000 -> 2206.674 | H40: =($E$7*$F$7*Q41*Q42)/1000 -> 2430.7893 | I40: =($E$7*$F$7*R41*R42)/1000 -> 1770.1417 | J40: =($E$7*$F$7*S41*S42)/1000 -> 930.9406 | K40: =($E$7*$F$7*T41*T42)/1000 -> -96.049427 | M40: Duration [days] | N40: 15 | O40: 27 | P40: 28 | Q40: 28 | R40: 25 | S40: 28 | T40: 12
D41: =D9 -> Socle 1. (heated space) | E41: =($E$9*$F$9*N35*N36)/1000 -> 0 | F41: =($E$9*$F$9*O35*O36)/1000 -> 0 | G41: =($E$9*$F$9*P35*P36)/1000 -> 0 | H41: =($E$9*$F$9*Q35*Q36)/1000 -> 0 | I41: =($E$9*$F$9*R35*R36)/1000 -> 0 | J41: =($E$9*$F$9*S35*S36)/1000 -> 0 | K41: =($E$9*$F$9*T35*T36)/1000 -> 0 | M41: Δt [°C] | N41: =Building_data!$D8-'Losses env. before'!N43 -> 1.6 | O41: =Building_data!$D8-'Losses env. before'!O43 -> 7.4 | P41: =Building_data!$D8-'Losses env. before'!P43 -> 12.8 | Q41: =Building_data!$D8-'Losses env. before'!Q43 -> 14.1 | R41: =Building_data!$D8-'Losses env. before'!R43 -> 11.5 | S41: =Building_data!$D8-'Losses env. before'!S43 -> 5.4 | T41: =Building_data!$D8-'Losses env. before'!T43 -> -1.3
D42: =D10 -> 0 | E42: =($E$10*$F$10*N35*N36)/1000 -> 0 | F42: =($E$10*$F$10*O35*O36)/1000 -> 0 | G42: =($E$10*$F$10*P35*P36)/1000 -> 0 | H42: =($E$10*$F$10*Q35*Q36)/1000 -> 0 | I42: =($E$10*$F$10*R35*R36)/1000 -> 0 | J42: =($E$10*$F$10*S35*S36)/1000 -> 0 | K42: =($E$10*$F$10*T35*T36)/1000 -> 0 | M42: Duration [h] | N42: =N40*Building_data!$D13 -> 210 | O42: =O40*Building_data!$D13 -> 378 | P42: =P40*Building_data!$D13 -> 392 | Q42: =Q40*Building_data!$D13 -> 392 | R42: =R40*Building_data!$D13 -> 350 | S42: =S40*Building_data!$D13 -> 392 | T42: =T40*Building_data!$D13 -> 168
C43: Ground | D43: =D11 -> Socle 2 | E43: =($E$11*$F$11*N35*N36)/1000 -> 0 | F43: =($E$11*$F$11*O35*O36)/1000 -> 0 | G43: =($E$11*$F$11*P35*P36)/1000 -> 0 | H43: =($E$11*$F$11*Q35*Q36)/1000 -> 0 | I43: =($E$11*$F$11*R35*R36)/1000 -> 0 | J43: =($E$11*$F$11*S35*S36)/1000 -> 0 | K43: =($E$11*$F$11*T35*T36)/1000 -> 0
